[2025-08-11T20:45:29.141+0000] {taskinstance.py:1956} INFO - Dependencies all met for dep_context=non-requeueable deps ti=<TaskInstance: public_health_data_pipeline.create_postgres_table_if_not_exists manual__2025-08-11T20:45:28.519261+00:00 [queued]>
[2025-08-11T20:45:29.145+0000] {taskinstance.py:1956} INFO - Dependencies all met for dep_context=requeueable deps ti=<TaskInstance: public_health_data_pipeline.create_postgres_table_if_not_exists manual__2025-08-11T20:45:28.519261+00:00 [queued]>
[2025-08-11T20:45:29.146+0000] {taskinstance.py:2170} INFO - Starting attempt 1 of 1
[2025-08-11T20:45:29.151+0000] {taskinstance.py:2191} INFO - Executing <Task(_PythonDecoratedOperator): create_postgres_table_if_not_exists> on 2025-08-11 20:45:28.519261+00:00
[2025-08-11T20:45:29.154+0000] {standard_task_runner.py:60} INFO - Started process 254 to run task
[2025-08-11T20:45:29.156+0000] {standard_task_runner.py:87} INFO - Running: ['***', 'tasks', 'run', 'public_health_data_pipeline', 'create_postgres_table_if_not_exists', 'manual__2025-08-11T20:45:28.519261+00:00', '--job-id', '25', '--raw', '--subdir', 'DAGS_FOLDER/covid_data_pipeline.py', '--cfg-path', '/tmp/tmpix9_220v']
[2025-08-11T20:45:29.157+0000] {standard_task_runner.py:88} INFO - Job 25: Subtask create_postgres_table_if_not_exists
[2025-08-11T20:45:29.166+0000] {logging_mixin.py:188} WARNING - /home/***/.local/lib/python3.9/site-packages/***/settings.py:194 DeprecationWarning: The sql_alchemy_conn option in [core] has been moved to the sql_alchemy_conn option in [database] - the old setting has been used, but please update your config.
[2025-08-11T20:45:29.183+0000] {task_command.py:423} INFO - Running <TaskInstance: public_health_data_pipeline.create_postgres_table_if_not_exists manual__2025-08-11T20:45:28.519261+00:00 [running]> on host 11f02f5ab8bc
[2025-08-11T20:45:29.215+0000] {taskinstance.py:2480} INFO - Exporting env vars: AIRFLOW_CTX_DAG_OWNER='***' AIRFLOW_CTX_DAG_ID='public_health_data_pipeline' AIRFLOW_CTX_TASK_ID='create_postgres_table_if_not_exists' AIRFLOW_CTX_EXECUTION_DATE='2025-08-11T20:45:28.519261+00:00' AIRFLOW_CTX_TRY_NUMBER='1' AIRFLOW_CTX_DAG_RUN_ID='manual__2025-08-11T20:45:28.519261+00:00'
[2025-08-11T20:45:29.220+0000] {base.py:83} INFO - Using connection ID 'postgres_default' for task execution.
[2025-08-11T20:45:29.221+0000] {taskinstance.py:2698} ERROR - Task failed with exception
Traceback (most recent call last):
  File "/home/airflow/.local/lib/python3.9/site-packages/airflow/models/taskinstance.py", line 433, in _execute_task
    result = execute_callable(context=context, **execute_callable_kwargs)
  File "/home/airflow/.local/lib/python3.9/site-packages/airflow/decorators/base.py", line 241, in execute
    return_value = super().execute(context)
  File "/home/airflow/.local/lib/python3.9/site-packages/airflow/operators/python.py", line 199, in execute
    return_value = self.execute_callable()
  File "/home/airflow/.local/lib/python3.9/site-packages/airflow/operators/python.py", line 216, in execute_callable
    return self.python_callable(*self.op_args, **self.op_kwargs)
  File "/opt/airflow/dags/covid_data_pipeline.py", line 46, in create_postgres_table_if_not_exists
    pg_hook.run(create_table_sql)
  File "/home/airflow/.local/lib/python3.9/site-packages/airflow/providers/common/sql/hooks/sql.py", line 391, in run
    with closing(self.get_conn()) as conn:
  File "/home/airflow/.local/lib/python3.9/site-packages/airflow/providers/postgres/hooks/postgres.py", line 158, in get_conn
    self.conn = psycopg2.connect(**conn_args)
  File "/home/airflow/.local/lib/python3.9/site-packages/psycopg2/__init__.py", line 122, in connect
    conn = _connect(dsn, connection_factory=connection_factory, **kwasync)
psycopg2.OperationalError: connection to server at "postgres" (172.19.0.2), port 5433 failed: Connection refused
	Is the server running on that host and accepting TCP/IP connections?

[2025-08-11T20:45:29.226+0000] {taskinstance.py:1138} INFO - Marking task as FAILED. dag_id=public_health_data_pipeline, task_id=create_postgres_table_if_not_exists, execution_date=20250811T204528, start_date=20250811T204529, end_date=20250811T204529
[2025-08-11T20:45:29.231+0000] {standard_task_runner.py:107} ERROR - Failed to execute job 25 for task create_postgres_table_if_not_exists (connection to server at "postgres" (172.19.0.2), port 5433 failed: Connection refused
	Is the server running on that host and accepting TCP/IP connections?
; 254)
[2025-08-11T20:45:29.254+0000] {local_task_job_runner.py:234} INFO - Task exited with return code 1
[2025-08-11T20:45:29.267+0000] {taskinstance.py:3280} INFO - 0 downstream tasks scheduled from follow-on schedule check
