[2025-08-11T01:47:02.344+0000] {taskinstance.py:1956} INFO - Dependencies all met for dep_context=non-requeueable deps ti=<TaskInstance: public_health_data_pipeline.load_clean_data_to_postgres manual__2025-08-11T01:46:59.030710+00:00 [queued]>
[2025-08-11T01:47:02.347+0000] {taskinstance.py:1956} INFO - Dependencies all met for dep_context=requeueable deps ti=<TaskInstance: public_health_data_pipeline.load_clean_data_to_postgres manual__2025-08-11T01:46:59.030710+00:00 [queued]>
[2025-08-11T01:47:02.347+0000] {taskinstance.py:2170} INFO - Starting attempt 1 of 1
[2025-08-11T01:47:02.351+0000] {taskinstance.py:2191} INFO - Executing <Task(_PythonDecoratedOperator): load_clean_data_to_postgres> on 2025-08-11 01:46:59.030710+00:00
[2025-08-11T01:47:02.353+0000] {standard_task_runner.py:60} INFO - Started process 214 to run task
[2025-08-11T01:47:02.355+0000] {standard_task_runner.py:87} INFO - Running: ['***', 'tasks', 'run', 'public_health_data_pipeline', 'load_clean_data_to_postgres', 'manual__2025-08-11T01:46:59.030710+00:00', '--job-id', '29', '--raw', '--subdir', 'DAGS_FOLDER/covid_data_pipeline.py', '--cfg-path', '/tmp/tmpf66o41w7']
[2025-08-11T01:47:02.356+0000] {standard_task_runner.py:88} INFO - Job 29: Subtask load_clean_data_to_postgres
[2025-08-11T01:47:02.372+0000] {task_command.py:423} INFO - Running <TaskInstance: public_health_data_pipeline.load_clean_data_to_postgres manual__2025-08-11T01:46:59.030710+00:00 [running]> on host 21f3fb7e4802
[2025-08-11T01:47:02.475+0000] {taskinstance.py:2480} INFO - Exporting env vars: AIRFLOW_CTX_DAG_OWNER='***' AIRFLOW_CTX_DAG_ID='public_health_data_pipeline' AIRFLOW_CTX_TASK_ID='load_clean_data_to_postgres' AIRFLOW_CTX_EXECUTION_DATE='2025-08-11T01:46:59.030710+00:00' AIRFLOW_CTX_TRY_NUMBER='1' AIRFLOW_CTX_DAG_RUN_ID='manual__2025-08-11T01:46:59.030710+00:00'
[2025-08-11T01:47:02.479+0000] {base.py:83} INFO - Using connection ID 'postgres_default' for task execution.
[2025-08-11T01:47:02.480+0000] {sql.py:450} INFO - Running statement: TRUNCATE TABLE covid_state_metrics;, parameters: None
[2025-08-11T01:47:02.483+0000] {taskinstance.py:2698} ERROR - Task failed with exception
Traceback (most recent call last):
  File "/home/airflow/.local/lib/python3.9/site-packages/airflow/models/taskinstance.py", line 433, in _execute_task
    result = execute_callable(context=context, **execute_callable_kwargs)
  File "/home/airflow/.local/lib/python3.9/site-packages/airflow/decorators/base.py", line 241, in execute
    return_value = super().execute(context)
  File "/home/airflow/.local/lib/python3.9/site-packages/airflow/operators/python.py", line 199, in execute
    return_value = self.execute_callable()
  File "/home/airflow/.local/lib/python3.9/site-packages/airflow/operators/python.py", line 216, in execute_callable
    return self.python_callable(*self.op_args, **self.op_kwargs)
  File "/opt/airflow/dags/covid_data_pipeline.py", line 83, in load_clean_data_to_postgres
    pg_hook.copy_expert(
TypeError: copy_expert() got an unexpected keyword argument 'filename_or_buffer'
[2025-08-11T01:47:02.487+0000] {taskinstance.py:1138} INFO - Marking task as FAILED. dag_id=public_health_data_pipeline, task_id=load_clean_data_to_postgres, execution_date=20250811T014659, start_date=20250811T014702, end_date=20250811T014702
[2025-08-11T01:47:02.491+0000] {standard_task_runner.py:107} ERROR - Failed to execute job 29 for task load_clean_data_to_postgres (copy_expert() got an unexpected keyword argument 'filename_or_buffer'; 214)
[2025-08-11T01:47:02.534+0000] {local_task_job_runner.py:234} INFO - Task exited with return code 1
[2025-08-11T01:47:02.542+0000] {taskinstance.py:3280} INFO - 0 downstream tasks scheduled from follow-on schedule check
