[2025-08-11T01:10:35.331+0000] {taskinstance.py:1956} INFO - Dependencies all met for dep_context=non-requeueable deps ti=<TaskInstance: public_health_data_pipeline.create_postgres_table_if_not_exists scheduled__2025-08-10T00:00:00+00:00 [queued]>
[2025-08-11T01:10:35.338+0000] {taskinstance.py:1956} INFO - Dependencies all met for dep_context=requeueable deps ti=<TaskInstance: public_health_data_pipeline.create_postgres_table_if_not_exists scheduled__2025-08-10T00:00:00+00:00 [queued]>
[2025-08-11T01:10:35.339+0000] {taskinstance.py:2170} INFO - Starting attempt 1 of 1
[2025-08-11T01:10:35.350+0000] {taskinstance.py:2191} INFO - Executing <Task(_PythonDecoratedOperator): create_postgres_table_if_not_exists> on 2025-08-10 00:00:00+00:00
[2025-08-11T01:10:35.355+0000] {standard_task_runner.py:60} INFO - Started process 202 to run task
[2025-08-11T01:10:35.358+0000] {standard_task_runner.py:87} INFO - Running: ['***', 'tasks', 'run', 'public_health_data_pipeline', 'create_postgres_table_if_not_exists', 'scheduled__2025-08-10T00:00:00+00:00', '--job-id', '2', '--raw', '--subdir', 'DAGS_FOLDER/covid_data_pipeline.py', '--cfg-path', '/tmp/tmpuux9002p']
[2025-08-11T01:10:35.360+0000] {standard_task_runner.py:88} INFO - Job 2: Subtask create_postgres_table_if_not_exists
[2025-08-11T01:10:35.401+0000] {task_command.py:423} INFO - Running <TaskInstance: public_health_data_pipeline.create_postgres_table_if_not_exists scheduled__2025-08-10T00:00:00+00:00 [running]> on host 1a355213c5ce
[2025-08-11T01:10:35.461+0000] {taskinstance.py:2480} INFO - Exporting env vars: AIRFLOW_CTX_DAG_OWNER='***' AIRFLOW_CTX_DAG_ID='public_health_data_pipeline' AIRFLOW_CTX_TASK_ID='create_postgres_table_if_not_exists' AIRFLOW_CTX_EXECUTION_DATE='2025-08-10T00:00:00+00:00' AIRFLOW_CTX_TRY_NUMBER='1' AIRFLOW_CTX_DAG_RUN_ID='scheduled__2025-08-10T00:00:00+00:00'
[2025-08-11T01:10:35.468+0000] {base.py:83} INFO - Using connection ID 'postgres_default' for task execution.
[2025-08-11T01:10:35.523+0000] {taskinstance.py:2698} ERROR - Task failed with exception
Traceback (most recent call last):
  File "/home/airflow/.local/lib/python3.9/site-packages/airflow/models/taskinstance.py", line 433, in _execute_task
    result = execute_callable(context=context, **execute_callable_kwargs)
  File "/home/airflow/.local/lib/python3.9/site-packages/airflow/decorators/base.py", line 241, in execute
    return_value = super().execute(context)
  File "/home/airflow/.local/lib/python3.9/site-packages/airflow/operators/python.py", line 199, in execute
    return_value = self.execute_callable()
  File "/home/airflow/.local/lib/python3.9/site-packages/airflow/operators/python.py", line 216, in execute_callable
    return self.python_callable(*self.op_args, **self.op_kwargs)
  File "/opt/airflow/dags/covid_data_pipeline.py", line 48, in create_postgres_table_if_not_exists
    pg_hook.run(create_table_sql)
  File "/home/airflow/.local/lib/python3.9/site-packages/airflow/providers/common/sql/hooks/sql.py", line 391, in run
    with closing(self.get_conn()) as conn:
  File "/home/airflow/.local/lib/python3.9/site-packages/airflow/providers/postgres/hooks/postgres.py", line 158, in get_conn
    self.conn = psycopg2.connect(**conn_args)
  File "/home/airflow/.local/lib/python3.9/site-packages/psycopg2/__init__.py", line 122, in connect
    conn = _connect(dsn, connection_factory=connection_factory, **kwasync)
psycopg2.OperationalError: could not translate host name "postgres" to address: Name or service not known

[2025-08-11T01:10:35.533+0000] {taskinstance.py:1138} INFO - Marking task as FAILED. dag_id=public_health_data_pipeline, task_id=create_postgres_table_if_not_exists, execution_date=20250810T000000, start_date=20250811T011035, end_date=20250811T011035
[2025-08-11T01:10:35.545+0000] {standard_task_runner.py:107} ERROR - Failed to execute job 2 for task create_postgres_table_if_not_exists (could not translate host name "postgres" to address: Name or service not known
; 202)
[2025-08-11T01:10:35.585+0000] {local_task_job_runner.py:234} INFO - Task exited with return code 1
[2025-08-11T01:10:35.602+0000] {taskinstance.py:3280} INFO - 0 downstream tasks scheduled from follow-on schedule check
[2025-08-11T01:54:56.229+0000] {taskinstance.py:1956} INFO - Dependencies all met for dep_context=non-requeueable deps ti=<TaskInstance: public_health_data_pipeline.create_postgres_table_if_not_exists scheduled__2025-08-10T00:00:00+00:00 [queued]>
[2025-08-11T01:54:56.233+0000] {taskinstance.py:1956} INFO - Dependencies all met for dep_context=requeueable deps ti=<TaskInstance: public_health_data_pipeline.create_postgres_table_if_not_exists scheduled__2025-08-10T00:00:00+00:00 [queued]>
[2025-08-11T01:54:56.234+0000] {taskinstance.py:2170} INFO - Starting attempt 1 of 1
[2025-08-11T01:54:56.239+0000] {taskinstance.py:2191} INFO - Executing <Task(_PythonDecoratedOperator): create_postgres_table_if_not_exists> on 2025-08-10 00:00:00+00:00
[2025-08-11T01:54:56.241+0000] {standard_task_runner.py:60} INFO - Started process 175 to run task
[2025-08-11T01:54:56.243+0000] {standard_task_runner.py:87} INFO - Running: ['***', 'tasks', 'run', 'public_health_data_pipeline', 'create_postgres_table_if_not_exists', 'scheduled__2025-08-10T00:00:00+00:00', '--job-id', '3', '--raw', '--subdir', 'DAGS_FOLDER/covid_data_pipeline.py', '--cfg-path', '/tmp/tmp_k7xc6e7']
[2025-08-11T01:54:56.245+0000] {standard_task_runner.py:88} INFO - Job 3: Subtask create_postgres_table_if_not_exists
[2025-08-11T01:54:56.269+0000] {task_command.py:423} INFO - Running <TaskInstance: public_health_data_pipeline.create_postgres_table_if_not_exists scheduled__2025-08-10T00:00:00+00:00 [running]> on host a09e668f8262
[2025-08-11T01:54:56.307+0000] {taskinstance.py:2480} INFO - Exporting env vars: AIRFLOW_CTX_DAG_OWNER='***' AIRFLOW_CTX_DAG_ID='public_health_data_pipeline' AIRFLOW_CTX_TASK_ID='create_postgres_table_if_not_exists' AIRFLOW_CTX_EXECUTION_DATE='2025-08-10T00:00:00+00:00' AIRFLOW_CTX_TRY_NUMBER='1' AIRFLOW_CTX_DAG_RUN_ID='scheduled__2025-08-10T00:00:00+00:00'
[2025-08-11T01:54:56.313+0000] {base.py:83} INFO - Using connection ID 'postgres_default' for task execution.
[2025-08-11T01:54:56.361+0000] {taskinstance.py:2698} ERROR - Task failed with exception
Traceback (most recent call last):
  File "/home/airflow/.local/lib/python3.9/site-packages/airflow/models/taskinstance.py", line 433, in _execute_task
    result = execute_callable(context=context, **execute_callable_kwargs)
  File "/home/airflow/.local/lib/python3.9/site-packages/airflow/decorators/base.py", line 241, in execute
    return_value = super().execute(context)
  File "/home/airflow/.local/lib/python3.9/site-packages/airflow/operators/python.py", line 199, in execute
    return_value = self.execute_callable()
  File "/home/airflow/.local/lib/python3.9/site-packages/airflow/operators/python.py", line 216, in execute_callable
    return self.python_callable(*self.op_args, **self.op_kwargs)
  File "/opt/airflow/dags/covid_data_pipeline.py", line 45, in create_postgres_table_if_not_exists
    pg_hook.run(create_table_sql)
  File "/home/airflow/.local/lib/python3.9/site-packages/airflow/providers/common/sql/hooks/sql.py", line 391, in run
    with closing(self.get_conn()) as conn:
  File "/home/airflow/.local/lib/python3.9/site-packages/airflow/providers/postgres/hooks/postgres.py", line 158, in get_conn
    self.conn = psycopg2.connect(**conn_args)
  File "/home/airflow/.local/lib/python3.9/site-packages/psycopg2/__init__.py", line 122, in connect
    conn = _connect(dsn, connection_factory=connection_factory, **kwasync)
psycopg2.OperationalError: could not translate host name "postgres" to address: Name or service not known

[2025-08-11T01:54:56.365+0000] {taskinstance.py:1138} INFO - Marking task as FAILED. dag_id=public_health_data_pipeline, task_id=create_postgres_table_if_not_exists, execution_date=20250810T000000, start_date=20250811T015456, end_date=20250811T015456
[2025-08-11T01:54:56.369+0000] {standard_task_runner.py:107} ERROR - Failed to execute job 3 for task create_postgres_table_if_not_exists (could not translate host name "postgres" to address: Name or service not known
; 175)
[2025-08-11T01:54:56.380+0000] {local_task_job_runner.py:234} INFO - Task exited with return code 1
[2025-08-11T01:54:56.403+0000] {taskinstance.py:3280} INFO - 0 downstream tasks scheduled from follow-on schedule check
[2025-08-11T17:19:05.412+0000] {taskinstance.py:1956} INFO - Dependencies all met for dep_context=non-requeueable deps ti=<TaskInstance: public_health_data_pipeline.create_postgres_table_if_not_exists scheduled__2025-08-10T00:00:00+00:00 [queued]>
[2025-08-11T17:19:05.428+0000] {taskinstance.py:1956} INFO - Dependencies all met for dep_context=requeueable deps ti=<TaskInstance: public_health_data_pipeline.create_postgres_table_if_not_exists scheduled__2025-08-10T00:00:00+00:00 [queued]>
[2025-08-11T17:19:05.432+0000] {taskinstance.py:2170} INFO - Starting attempt 1 of 1
[2025-08-11T17:19:05.449+0000] {taskinstance.py:2191} INFO - Executing <Task(_PythonDecoratedOperator): create_postgres_table_if_not_exists> on 2025-08-10 00:00:00+00:00
[2025-08-11T17:19:05.459+0000] {standard_task_runner.py:60} INFO - Started process 175 to run task
[2025-08-11T17:19:05.462+0000] {standard_task_runner.py:87} INFO - Running: ['***', 'tasks', 'run', 'public_health_data_pipeline', 'create_postgres_table_if_not_exists', 'scheduled__2025-08-10T00:00:00+00:00', '--job-id', '2', '--raw', '--subdir', 'DAGS_FOLDER/covid_data_pipeline.py', '--cfg-path', '/tmp/tmpu759ohd4']
[2025-08-11T17:19:05.464+0000] {standard_task_runner.py:88} INFO - Job 2: Subtask create_postgres_table_if_not_exists
[2025-08-11T17:19:05.481+0000] {logging_mixin.py:188} WARNING - /home/***/.local/lib/python3.9/site-packages/***/settings.py:194 DeprecationWarning: The sql_alchemy_conn option in [core] has been moved to the sql_alchemy_conn option in [database] - the old setting has been used, but please update your config.
[2025-08-11T17:19:05.539+0000] {task_command.py:423} INFO - Running <TaskInstance: public_health_data_pipeline.create_postgres_table_if_not_exists scheduled__2025-08-10T00:00:00+00:00 [running]> on host b5053c93029b
[2025-08-11T17:19:05.633+0000] {taskinstance.py:2480} INFO - Exporting env vars: AIRFLOW_CTX_DAG_OWNER='***' AIRFLOW_CTX_DAG_ID='public_health_data_pipeline' AIRFLOW_CTX_TASK_ID='create_postgres_table_if_not_exists' AIRFLOW_CTX_EXECUTION_DATE='2025-08-10T00:00:00+00:00' AIRFLOW_CTX_TRY_NUMBER='1' AIRFLOW_CTX_DAG_RUN_ID='scheduled__2025-08-10T00:00:00+00:00'
[2025-08-11T17:19:05.648+0000] {base.py:83} INFO - Using connection ID 'postgres_default' for task execution.
[2025-08-11T17:19:05.653+0000] {taskinstance.py:2698} ERROR - Task failed with exception
Traceback (most recent call last):
  File "/home/airflow/.local/lib/python3.9/site-packages/airflow/models/taskinstance.py", line 433, in _execute_task
    result = execute_callable(context=context, **execute_callable_kwargs)
  File "/home/airflow/.local/lib/python3.9/site-packages/airflow/decorators/base.py", line 241, in execute
    return_value = super().execute(context)
  File "/home/airflow/.local/lib/python3.9/site-packages/airflow/operators/python.py", line 199, in execute
    return_value = self.execute_callable()
  File "/home/airflow/.local/lib/python3.9/site-packages/airflow/operators/python.py", line 216, in execute_callable
    return self.python_callable(*self.op_args, **self.op_kwargs)
  File "/opt/airflow/dags/covid_data_pipeline.py", line 46, in create_postgres_table_if_not_exists
    pg_hook.run(create_table_sql)
  File "/home/airflow/.local/lib/python3.9/site-packages/airflow/providers/common/sql/hooks/sql.py", line 391, in run
    with closing(self.get_conn()) as conn:
  File "/home/airflow/.local/lib/python3.9/site-packages/airflow/providers/postgres/hooks/postgres.py", line 158, in get_conn
    self.conn = psycopg2.connect(**conn_args)
  File "/home/airflow/.local/lib/python3.9/site-packages/psycopg2/__init__.py", line 122, in connect
    conn = _connect(dsn, connection_factory=connection_factory, **kwasync)
psycopg2.OperationalError: connection to server at "postgres" (172.19.0.2), port 5432 failed: FATAL:  password authentication failed for user "postgres"

[2025-08-11T17:19:05.669+0000] {taskinstance.py:1138} INFO - Marking task as FAILED. dag_id=public_health_data_pipeline, task_id=create_postgres_table_if_not_exists, execution_date=20250810T000000, start_date=20250811T171905, end_date=20250811T171905
[2025-08-11T17:19:05.691+0000] {standard_task_runner.py:107} ERROR - Failed to execute job 2 for task create_postgres_table_if_not_exists (connection to server at "postgres" (172.19.0.2), port 5432 failed: FATAL:  password authentication failed for user "postgres"
; 175)
[2025-08-11T17:19:05.729+0000] {local_task_job_runner.py:234} INFO - Task exited with return code 1
[2025-08-11T17:19:05.798+0000] {taskinstance.py:3280} INFO - 0 downstream tasks scheduled from follow-on schedule check
